Workbook
Name Active: 'Analysis '!$E$8
Name activestaff: 'Analysis '!$F$14
Name Attritionrate: 'Analysis '!$C$32
Name AVERAGESALARY: 'Analysis '!$C$4
Name Bonusamount: 'Analysis '!$D$4
Name HEADCOUNT: 'Analysis '!$A$4
Name Left: 'Analysis '!$E$9
Name leftstaff: 'Analysis '!$F$15
Name Overallattrition: 'Analysis '!$E$4
Name Resigned: 'Analysis '!$E$10
Name resignedstaff: 'Analysis '!$F$16
Name RESIGNEDTOTAL: 'Analysis '!$C$37
Name SALARY: 'Analysis '!$B$4
Name Slicer_Department: #N/A
Name Slicer_Employment_Status: #N/A
Name Slicer_Performance_Band: #N/A
Name Slicer_Years: #N/A
Name total: 'Analysis '!$B$3:$B$4
Name TOTALSALARY: 'Analysis '!$B$3:$B$4

Sheet Lookup_Departments
A1: Dept_Code | B1: Department_Name
A2: HR01 | B2: Human Resources
A3: IT02 | B3: Information Technology
A4: FIN03 | B4: Finance
A5: MKT04 | B5: Marketing
A6: SAL05 | B6: Sales
A7: OPS06 | B7: Operations

Sheet Lookup_Performance
A1: Min_Score | B1: Max_Score | C1: Performance_Band | D1: Bonus_Percentage
A2: 0 | B2: 49 | C2: Needs Improvement | D2: 0
A3: 50 | B3: 69 | C3: Developing | D3: 0.02
A4: 70 | B4: 84 | C4: Achieving | D4: 0.05
A5: 85 | B5: 94 | C5: Exceeding | D5: 0.08
A6: 95 | B6: 100 | C6: Outstanding | D6: 0.12

Sheet Raw_Employee_Data
A1: Emp ID | B1: First_Name | C1: Last_Name | D1: Dept Code | E1: Hire Date | F1: Salary | G1: Perf_Score | H1: Employment Status
A2: EMP127 | B2: Emily | C2: Brown | D2: IT02 | E2: 43093 | F2: 50361 | G2: 52 | H2: active
A3: EMP046 | B3: Richard | C3: Hernandez | D3: MKT04 | E3: 44659 | F3: 112673 | H3: ACTIVE
A4: EMP134 | B4: Emily | C4: Gonzalez | D4: IT02 | E4: 42431 | F4: $114,425 | G4: 54 | H4: LEFT
A5: EMP139 | B5: John | C5: Martinez | D5: FIN03 | E5: 45110 | F5: 103831 | G5: 70 | H5: active
A6: EMP112 | B6: Thomas | C6: Smith | D6: IT02 | E6: 44977 | F6: 73785 | G6: 40 | H6: Left
A7: EMP030 | B7: Emily | C7: Johnson | D7: OPS06 | E7: 02-Mar-20 | F7: 115882 | G7: 49 | H7: ACTIVE
A8: EMP096 | B8: John | C8: Wilson | D8: OPS06 | E8: 45272 | F8: 59980 | G8: 70 | H8: Left
A9: EMP098 | B9: Jessica | C9: Smith | D9: OPS06 | E9: 44174 | F9: 68728 | G9: 45 | H9: ACTIVE
A10: EMP095 | C10: Rodriguez | D10: FIN03 | E10: 43107 | F10: 102139 | G10: 79 | H10: active
A11: EMP140 | B11: Michael | C11: Martinez | D11: SAL05 | E11: 42676 | F11: 94998 | G11: 58 | H11: Active
A12: EMP020 | B12: Emily | C12: Miller | D12: sal05 | E12: 43911 | F12: $118,635 | G12: 49 | H12: Active
A13: EMP057 | B13: Emily | C13: Hernandez | D13: IT02 | E13: 42425 | F13: 76918 | G13: 62 | H13: Actv
A14: EMP016 | B14: Jane | C14: Williams | D14: mkt04 | E14: 17-Jun-21 | F14: 61408 | G14: 48 | H14: ACTIVE
A15: EMP070 | B15: Jane | C15: Miller | D15: MKT04 | E15: 44001 | F15: 99990 | G15: 54 | H15: Actv
A16: EMP025 | B16: Robert | C16: Jones | D16: MKT04 | E16: 43820 | F16: 80385 | H16: active
A17: EMP031 | B17: Thomas | C17: Rodriguez | D17: SAL05 | E17: 45169 | F17: 65290 | G17: 77 | H17: active
A18: EMP126 | B18: Emily | C18: Davis | D18: IT02 | E18: 42337 | F18: 105765 | G18: 42 | H18: Active
A19: EMP109 | B19: James | C19: Martinez | D19: SAL05 | E19: 42899 | F19: 102921 | G19: 49 | H19: ACTIVE
A20: EMP057 | B20: Emily | C20: Hernandez | D20: IT02 | E20: 42425 | F20: 76918 | G20: 62 | H20: Actv
A21: EMP066 | B21: Ashley | C21: Lopez | D21: MKT04 | E21: 43235 | F21: 73984 | G21: 93 | H21: Actv
A22: EMP120 | B22: Amanda | C22: Gonzalez | D22: IT02 | E22: 42575 | G22: 75 | H22: Actv
A23: EMP019 | B23: Michael | C23: Hernandez | D23: FIN03 | E23: 43076 | F23: 118527 | G23: 50 | H23: Actv
A24: EMP013 | B24: Richard | C24: Hernandez | D24: MKT04 | E24: 44353 | F24: 107871 | G24: 88 | H24: active
A25: EMP010 | B25: Michael | C25: Rodriguez | D25: IT02 | E25: 44815 | F25: 93956 | G25: 50 | H25: LEFT
A26: EMP032 | B26: Jessica | C26: Johnson | D26: FIN03 | E26: 42565 | F26: 100851 | G26: 64 | H26: ACTIVE
A27: EMP082 | B27: Ashley | C27: Williams | D27: SAL05 | E27: 44728 | F27: 68655 | G27: 32 | H27: active
A28: EMP052 | C28: Williams | D28: SAL05 | E28: 45134 | F28: 81205 | G28: 59 | H28: Actv
A29: EMP129 | B29: John | C29: Wilson | D29: SAL05 | E29: 09/24/2019 | F29: $77,610 | G29: 88 | H29: Actv
A30: EMP146 | B30: Thomas | C30: Rodriguez | D30: it02 | E30: 44765 | F30: $50,873 | G30: 90 | H30: Active
A31: EMP099 | B31: Michael | C31: Wilson | D31: fin03 | E31: 13-May-18 | F31: 85312 | G31: 66 | H31: active
A32: EMP015 | B32: John | C32: Rodriguez | D32: SAL05 | E32: 42202 | G32: 68 | H32: active
A33: EMP076 | B33: Thomas | C33: Hernandez | D33: OPS06 | E33: 05-Aug-15 | F33: 97055 | G33: 80 | H33: Actv
A34: EMP137 | B34: Michael | C34: Johnson | D34: IT02 | E34: 45195 | F34: 66069 | G34: 72 | H34: Actv
A35: EMP056 | B35: Sarah | C35: Brown | D35: it02 | E35: 10-Jun-19 | F35: 90157 | G35: 58 | H35: active
A36: EMP125 | B36: Jane | C36: Martinez | D36: HR01 | E36: 44578 | F36: 59899 | G36: 78 | H36: Actv
A37: EMP085 | B37: Emily | C37: Jones | D37: FIN03 | E37: 03-Jul-17 | F37: 113389 | G37: 30 | H37: ACTIVE
A38: EMP106 | C38: Brown | D38: IT02 | E38: 01-Sep-15 | F38: 102691 | G38: 52 | H38: Active
A39: EMP043 | B39: John | C39: Wilson | D39: OPS06 | E39: 03-Aug-22 | F39: 111845 | G39: 98 | H39: active
A40: EMP068 | B40: Melissa | C40: Brown | D40: SAL05 | E40: 06/29/2022 | F40: 69219 | G40: 93 | H40: Actv
...

Sheet Formula sheet
B1: Emp ID | C1: First_Name | D1: Last_Name | E1: Full Name | F1: Dept Code | G1: Dept Code | H1: Department | I1: Hire Date | J1: Years of Service | K1: Salary | L1: Average Salary | M1: Perf_Score | N1: Aveage score | O1: Performance Band | P1: Eligible Bonus | Q1: Eligible Bonus Amount | R1: Employment Status | S1: Employment Status
B2: EMP127 | C2: Emily | D2: Brown | E2: Emily Brown | F2: IT02 | G2: =UPPER(TRIM(F:F)) -> IT02 | H2: =VLOOKUP(G:G,Lookup_Departments!A:B,2,0) -> Information Technology | I2: 43093 | J2: =DATEDIF(I2,TODAY(),"Y") -> 8 | K2: 50361 | L2: =AVERAGE(K:K) -> 83603.931 | M2: 52 | N2: =AVERAGE(M:M) -> 67.647512 | O2: =IF(M2>95,"Outstanding",IF(M2>85,"Exceeding",IF(M2>70,"Achieving",IF(M2>50,"Developing",IF(M2<50,"Needs Improvement"))))) -> Developing | P2: =IF(M2>95,"0.12",IF(M2>85,"0.08",IF(M2>70,"0.05",IF(M2>50,"0.02",IF(M2<50,"0"))))) -> 0.02 | Q2: =K2*P2 -> 1007.22 | R2: active | S2: =PROPER(TRIM(R:R)) -> Active
B3: EMP046 | C3: Richard | D3: Hernandez | E3: Richard Hernandez | F3: MKT04 | G3: =UPPER(TRIM(F:F)) -> MKT04 | H3: =VLOOKUP(G:G,Lookup_Departments!A:B,2,0) -> Marketing | I3: 44659 | J3: =DATEDIF(I3,TODAY(),"Y") -> 4 | K3: 112673 | M3: 68.077465 | O3: =IF(M3>95,"Outstanding",IF(M3>85,"Exceeding",IF(M3>70,"Achieving",IF(M3>50,"Developing",IF(M3<50,"Needs Improvement"))))) -> Developing | P3: =IF(M3>95,"0.12",IF(M3>85,"0.08",IF(M3>70,"0.05",IF(M3>50,"0.02",IF(M3<50,"0"))))) -> 0.02 | Q3: =K3*P3 -> 2253.46 | R3: ACTIVE | S3: =PROPER(TRIM(R:R)) -> Active
B4: EMP134 | C4: Emily | D4: Gonzalez | E4: Emily Gonzalez | F4: IT02 | G4: =UPPER(TRIM(F:F)) -> IT02 | H4: =VLOOKUP(G:G,Lookup_Departments!A:B,2,0) -> Information Technology | I4: 42431 | J4: =DATEDIF(I4,TODAY(),"Y") -> 10 | K4: 114425 | M4: 54 | O4: =IF(M4>95,"Outstanding",IF(M4>85,"Exceeding",IF(M4>70,"Achieving",IF(M4>50,"Developing",IF(M4<50,"Needs Improvement"))))) -> Developing | P4: =IF(M4>95,"0.12",IF(M4>85,"0.08",IF(M4>70,"0.05",IF(M4>50,"0.02",IF(M4<50,"0"))))) -> 0.02 | Q4: =K4*P4 -> 2288.5 | R4: LEFT | S4: =PROPER(TRIM(R:R)) -> Left
B5: EMP139 | C5: John | D5: Martinez | E5: John Martinez | F5: FIN03 | G5: =UPPER(TRIM(F:F)) -> FIN03 | H5: =VLOOKUP(G:G,Lookup_Departments!A:B,2,0) -> Finance | I5: 45110 | J5: =DATEDIF(I5,TODAY(),"Y") -> 3 | K5: 103831 | M5: 70 | O5: =IF(M5>95,"Outstanding",IF(M5>85,"Exceeding",IF(M5>70,"Achieving",IF(M5>50,"Developing",IF(M5<50,"Needs Improvement"))))) -> Developing | P5: =IF(M5>95,"0.12",IF(M5>85,"0.08",IF(M5>70,"0.05",IF(M5>50,"0.02",IF(M5<50,"0"))))) -> 0.02 | Q5: =K5*P5 -> 2076.62 | R5: active | S5: =PROPER(TRIM(R:R)) -> Active
B6: EMP112 | C6: Thomas | D6: Smith | E6: Thomas Smith | F6: IT02 | G6: =UPPER(TRIM(F:F)) -> IT02 | H6: =VLOOKUP(G:G,Lookup_Departments!A:B,2,0) -> Information Technology | I6: 44977 | J6: =DATEDIF(I6,TODAY(),"Y") -> 3 | K6: 73785 | M6: 40 | O6: =IF(M6>95,"Outstanding",IF(M6>85,"Exceeding",IF(M6>70,"Achieving",IF(M6>50,"Developing",IF(M6<50,"Needs Improvement"))))) -> Needs Improvement | P6: =IF(M6>95,"0.12",IF(M6>85,"0.08",IF(M6>70,"0.05",IF(M6>50,"0.02",IF(M6<50,"0"))))) -> 0 | Q6: =K6*P6 -> 0 | R6: Left | S6: =PROPER(TRIM(R:R)) -> Left | W6: Full name : Flash fill
B7: EMP030 | C7: Emily | D7: Johnson | E7: Emily Johnson | F7: OPS06 | G7: =UPPER(TRIM(F:F)) -> OPS06 | H7: =VLOOKUP(G:G,Lookup_Departments!A:B,2,0) -> Operations | I7: 43892 | J7: =DATEDIF(I7,TODAY(),"Y") -> 6 | K7: 115882 | M7: 49 | O7: =IF(M7>95,"Outstanding",IF(M7>85,"Exceeding",IF(M7>70,"Achieving",IF(M7>50,"Developing",IF(M7<50,"Needs Improvement"))))) -> Needs Improvement | P7: =IF(M7>95,"0.12",IF(M7>85,"0.08",IF(M7>70,"0.05",IF(M7>50,"0.02",IF(M7<50,"0"))))) -> 0 | Q7: =K7*P7 -> 0 | R7: ACTIVE | S7: =PROPER(TRIM(R:R)) -> Active | W7: Dept code: Upper and trim
B8: EMP096 | C8: John | D8: Wilson | E8: John Wilson | F8: OPS06 | G8: =UPPER(TRIM(F:F)) -> OPS06 | H8: =VLOOKUP(G:G,Lookup_Departments!A:B,2,0) -> Operations | I8: 45272 | J8: =DATEDIF(I8,TODAY(),"Y") -> 2 | K8: 59980 | M8: 70 | O8: =IF(M8>95,"Outstanding",IF(M8>85,"Exceeding",IF(M8>70,"Achieving",IF(M8>50,"Developing",IF(M8<50,"Needs Improvement"))))) -> Developing | P8: =IF(M8>95,"0.12",IF(M8>85,"0.08",IF(M8>70,"0.05",IF(M8>50,"0.02",IF(M8<50,"0"))))) -> 0.02 | Q8: =K8*P8 -> 1199.6 | R8: Left | S8: =PROPER(TRIM(R:R)) -> Left | W8: Department: Vlookup
B9: EMP098 | C9: Jessica | D9: Smith | E9: Jessica Smith | F9: OPS06 | G9: =UPPER(TRIM(F:F)) -> OPS06 | H9: =VLOOKUP(G:G,Lookup_Departments!A:B,2,0) -> Operations | I9: 44174 | J9: =DATEDIF(I9,TODAY(),"Y") -> 5 | K9: 68728 | M9: 45 | O9: =IF(M9>95,"Outstanding",IF(M9>85,"Exceeding",IF(M9>70,"Achieving",IF(M9>50,"Developing",IF(M9<50,"Needs Improvement"))))) -> Needs Improvement | P9: =IF(M9>95,"0.12",IF(M9>85,"0.08",IF(M9>70,"0.05",IF(M9>50,"0.02",IF(M9<50,"0"))))) -> 0 | Q9: =K9*P9 -> 0 | R9: ACTIVE | S9: =PROPER(TRIM(R:R)) -> Active | W9: Hiring Date : Text to column
B10: EMP095 | C10: Rodriguez | D10: Rodriguez | E10: Rodriguez Rodriguez | F10: FIN03 | G10: =UPPER(TRIM(F:F)) -> FIN03 | H10: =VLOOKUP(G:G,Lookup_Departments!A:B,2,0) -> Finance | I10: 43107 | J10: =DATEDIF(I10,TODAY(),"Y") -> 8 | K10: 102139 | M10: 79 | O10: =IF(M10>95,"Outstanding",IF(M10>85,"Exceeding",IF(M10>70,"Achieving",IF(M10>50,"Developing",IF(M10<50,"Needs Improvement"))))) -> Achieving | P10: =IF(M10>95,"0.12",IF(M10>85,"0.08",IF(M10>70,"0.05",IF(M10>50,"0.02",IF(M10<50,"0"))))) -> 0.05 | Q10: =K10*P10 -> 5106.95 | R10: active | S10: =PROPER(TRIM(R:R)) -> Active | W10: Emepty Salary sapce was filled with Averagesalary
B11: EMP140 | C11: Michael | D11: Martinez | E11: Michael Martinez | F11: SAL05 | G11: =UPPER(TRIM(F:F)) -> SAL05 | H11: =VLOOKUP(G:G,Lookup_Departments!A:B,2,0) -> Sales | I11: 42676 | J11: =DATEDIF(I11,TODAY(),"Y") -> 9 | K11: 94998 | M11: 58 | O11: =IF(M11>95,"Outstanding",IF(M11>85,"Exceeding",IF(M11>70,"Achieving",IF(M11>50,"Developing",IF(M11<50,"Needs Improvement"))))) -> Developing | P11: =IF(M11>95,"0.12",IF(M11>85,"0.08",IF(M11>70,"0.05",IF(M11>50,"0.02",IF(M11<50,"0"))))) -> 0.02 | Q11: =K11*P11 -> 1899.96 | R11: Active | S11: =PROPER(TRIM(R:R)) -> Active | W11: Performance_Band: if function
B12: EMP020 | C12: Emily | D12: Miller | E12: Emily Miller | F12: sal05 | G12: =UPPER(TRIM(F:F)) -> SAL05 | H12: =VLOOKUP(G:G,Lookup_Departments!A:B,2,0) -> Sales | I12: 43911 | J12: =DATEDIF(I12,TODAY(),"Y") -> 6 | K12: 118635 | M12: 49 | O12: =IF(M12>95,"Outstanding",IF(M12>85,"Exceeding",IF(M12>70,"Achieving",IF(M12>50,"Developing",IF(M12<50,"Needs Improvement"))))) -> Needs Improvement | P12: =IF(M12>95,"0.12",IF(M12>85,"0.08",IF(M12>70,"0.05",IF(M12>50,"0.02",IF(M12<50,"0"))))) -> 0 | Q12: =K12*P12 -> 0 | R12: Active | S12: =PROPER(TRIM(R:R)) -> Active | W12: Eligibility Bonus : If function
B13: EMP057 | C13: Emily | D13: Hernandez | E13: Emily Hernandez | F13: IT02 | G13: =UPPER(TRIM(F:F)) -> IT02 | H13: =VLOOKUP(G:G,Lookup_Departments!A:B,2,0) -> Information Technology | I13: 42425 | J13: =DATEDIF(I13,TODAY(),"Y") -> 10 | K13: 76918 | M13: 62 | O13: =IF(M13>95,"Outstanding",IF(M13>85,"Exceeding",IF(M13>70,"Achieving",IF(M13>50,"Developing",IF(M13<50,"Needs Improvement"))))) -> Developing | P13: =IF(M13>95,"0.12",IF(M13>85,"0.08",IF(M13>70,"0.05",IF(M13>50,"0.02",IF(M13<50,"0"))))) -> 0.02 | Q13: =K13*P13 -> 1538.36 | R13: Active | S13: =PROPER(TRIM(R:R)) -> Active | W13: Employment Status: Proper trim
B14: EMP016 | C14: Jane | D14: Williams | E14: Jane Williams | F14: mkt04 | G14: =UPPER(TRIM(F:F)) -> MKT04 | H14: =VLOOKUP(G:G,Lookup_Departments!A:B,2,0) -> Marketing | I14: 44364 | J14: =DATEDIF(I14,TODAY(),"Y") -> 5 | K14: 61408 | M14: 48 | O14: =IF(M14>95,"Outstanding",IF(M14>85,"Exceeding",IF(M14>70,"Achieving",IF(M14>50,"Developing",IF(M14<50,"Needs Improvement"))))) -> Needs Improvement | P14: =IF(M14>95,"0.12",IF(M14>85,"0.08",IF(M14>70,"0.05",IF(M14>50,"0.02",IF(M14<50,"0"))))) -> 0 | Q14: =K14*P14 -> 0 | R14: ACTIVE | S14: =PROPER(TRIM(R:R)) -> Active | W14: Years of Service: Datedif
B15: EMP070 | C15: Jane | D15: Miller | E15: Jane Miller | F15: MKT04 | G15: =UPPER(TRIM(F:F)) -> MKT04 | H15: =VLOOKUP(G:G,Lookup_Departments!A:B,2,0) -> Marketing | I15: 44001 | J15: =DATEDIF(I15,TODAY(),"Y") -> 6 | K15: 99990 | M15: 54 | O15: =IF(M15>95,"Outstanding",IF(M15>85,"Exceeding",IF(M15>70,"Achieving",IF(M15>50,"Developing",IF(M15<50,"Needs Improvement"))))) -> Developing | P15: =IF(M15>95,"0.12",IF(M15>85,"0.08",IF(M15>70,"0.05",IF(M15>50,"0.02",IF(M15<50,"0"))))) -> 0.02 | Q15: =K15*P15 -> 1999.8 | R15: Active | S15: =PROPER(TRIM(R:R)) -> Active
B16: EMP025 | C16: Robert | D16: Jones | E16: Robert Jones | F16: MKT04 | G16: =UPPER(TRIM(F:F)) -> MKT04 | H16: =VLOOKUP(G:G,Lookup_Departments!A:B,2,0) -> Marketing | I16: 43820 | J16: =DATEDIF(I16,TODAY(),"Y") -> 6 | K16: 80385 | M16: 68.077465 | O16: =IF(M16>95,"Outstanding",IF(M16>85,"Exceeding",IF(M16>70,"Achieving",IF(M16>50,"Developing",IF(M16<50,"Needs Improvement"))))) -> Developing | P16: =IF(M16>95,"0.12",IF(M16>85,"0.08",IF(M16>70,"0.05",IF(M16>50,"0.02",IF(M16<50,"0"))))) -> 0.02 | Q16: =K16*P16 -> 1607.7 | R16: active | S16: =PROPER(TRIM(R:R)) -> Active
B17: EMP031 | C17: Thomas | D17: Rodriguez | E17: Thomas Rodriguez | F17: SAL05 | G17: =UPPER(TRIM(F:F)) -> SAL05 | H17: =VLOOKUP(G:G,Lookup_Departments!A:B,2,0) -> Sales | I17: 45169 | J17: =DATEDIF(I17,TODAY(),"Y") -> 2 | K17: 65290 | M17: 68.077465 | O17: =IF(M17>95,"Outstanding",IF(M17>85,"Exceeding",IF(M17>70,"Achieving",IF(M17>50,"Developing",IF(M17<50,"Needs Improvement"))))) -> Developing | P17: =IF(M17>95,"0.12",IF(M17>85,"0.08",IF(M17>70,"0.05",IF(M17>50,"0.02",IF(M17<50,"0"))))) -> 0.02 | Q17: =K17*P17 -> 1305.8 | R17: active | S17: =PROPER(TRIM(R:R)) -> Active
B18: EMP126 | C18: Emily | D18: Davis | E18: Emily Davis | F18: IT02 | G18: =UPPER(TRIM(F:F)) -> IT02 | H18: =VLOOKUP(G:G,Lookup_Departments!A:B,2,0) -> Information Technology | I18: 42337 | J18: =DATEDIF(I18,TODAY(),"Y") -> 10 | K18: 105765 | M18: 68.077465 | O18: =IF(M18>95,"Outstanding",IF(M18>85,"Exceeding",IF(M18>70,"Achieving",IF(M18>50,"Developing",IF(M18<50,"Needs Improvement"))))) -> Developing | P18: =IF(M18>95,"0.12",IF(M18>85,"0.08",IF(M18>70,"0.05",IF(M18>50,"0.02",IF(M18<50,"0"))))) -> 0.02 | Q18: =K18*P18 -> 2115.3 | R18: Active | S18: =PROPER(TRIM(R:R)) -> Active
B19: EMP109 | C19: James | D19: Martinez | E19: James Martinez | F19: SAL05 | G19: =UPPER(TRIM(F:F)) -> SAL05 | H19: =VLOOKUP(G:G,Lookup_Departments!A:B,2,0) -> Sales | I19: 42899 | J19: =DATEDIF(I19,TODAY(),"Y") -> 9 | K19: 102921 | M19: 68.077465 | O19: =IF(M19>95,"Outstanding",IF(M19>85,"Exceeding",IF(M19>70,"Achieving",IF(M19>50,"Developing",IF(M19<50,"Needs Improvement"))))) -> Developing | P19: =IF(M19>95,"0.12",IF(M19>85,"0.08",IF(M19>70,"0.05",IF(M19>50,"0.02",IF(M19<50,"0"))))) -> 0.02 | Q19: =K19*P19 -> 2058.42 | R19: ACTIVE | S19: =PROPER(TRIM(R:R)) -> Active
B20: EMP066 | C20: Ashley | D20: Lopez | E20: Ashley Lopez | F20: MKT04 | G20: =UPPER(TRIM(F:F)) -> MKT04 | H20: =VLOOKUP(G:G,Lookup_Departments!A:B,2,0) -> Marketing | I20: 43235 | J20: =DATEDIF(I20,TODAY(),"Y") -> 8 | K20: 73984 | M20: 68.077465 | O20: =IF(M20>95,"Outstanding",IF(M20>85,"Exceeding",IF(M20>70,"Achieving",IF(M20>50,"Developing",IF(M20<50,"Needs Improvement"))))) -> Developing | P20: =IF(M20>95,"0.12",IF(M20>85,"0.08",IF(M20>70,"0.05",IF(M20>50,"0.02",IF(M20<50,"0"))))) -> 0.02 | Q20: =K20*P20 -> 1479.68 | R20: Active | S20: =PROPER(TRIM(R:R)) -> Active
B21: EMP120 | C21: Amanda | D21: Gonzalez | E21: Amanda Gonzalez | F21: IT02 | G21: =UPPER(TRIM(F:F)) -> IT02 | H21: =VLOOKUP(G:G,Lookup_Departments!A:B,2,0) -> Information Technology | I21: 42575 | J21: =DATEDIF(I21,TODAY(),"Y") -> 9 | K21: 83603.931 | M21: 68.077465 | O21: =IF(M21>95,"Outstanding",IF(M21>85,"Exceeding",IF(M21>70,"Achieving",IF(M21>50,"Developing",IF(M21<50,"Needs Improvement"))))) -> Developing | P21: =IF(M21>95,"0.12",IF(M21>85,"0.08",IF(M21>70,"0.05",IF(M21>50,"0.02",IF(M21<50,"0"))))) -> 0.02 | Q21: =K21*P21 -> 1672.0786 | R21: Active | S21: =PROPER(TRIM(R:R)) -> Active
B22: EMP019 | C22: Michael | D22: Hernandez | E22: Michael Hernandez | F22: FIN03 | G22: =UPPER(TRIM(F:F)) -> FIN03 | H22: =VLOOKUP(G:G,Lookup_Departments!A:B,2,0) -> Finance | I22: 43076 | J22: =DATEDIF(I22,TODAY(),"Y") -> 8 | K22: 118527 | M22: 68.077465 | O22: =IF(M22>95,"Outstanding",IF(M22>85,"Exceeding",IF(M22>70,"Achieving",IF(M22>50,"Developing",IF(M22<50,"Needs Improvement"))))) -> Developing | P22: =IF(M22>95,"0.12",IF(M22>85,"0.08",IF(M22>70,"0.05",IF(M22>50,"0.02",IF(M22<50,"0"))))) -> 0.02 | Q22: =K22*P22 -> 2370.54 | R22: Active | S22: =PROPER(TRIM(R:R)) -> Active
B23: EMP013 | C23: Richard | D23: Hernandez | E23: Richard Hernandez | F23: MKT04 | G23: =UPPER(TRIM(F:F)) -> MKT04 | H23: =VLOOKUP(G:G,Lookup_Departments!A:B,2,0) -> Marketing | I23: 44353 | J23: =DATEDIF(I23,TODAY(),"Y") -> 5 | K23: 107871 | M23: 68.077465 | O23: =IF(M23>95,"Outstanding",IF(M23>85,"Exceeding",IF(M23>70,"Achieving",IF(M23>50,"Developing",IF(M23<50,"Needs Improvement"))))) -> Developing | P23: =IF(M23>95,"0.12",IF(M23>85,"0.08",IF(M23>70,"0.05",IF(M23>50,"0.02",IF(M23<50,"0"))))) -> 0.02 | Q23: =K23*P23 -> 2157.42 | R23: active | S23: =PROPER(TRIM(R:R)) -> Active
B24: EMP010 | C24: Michael | D24: Rodriguez | E24: Michael Rodriguez | F24: IT02 | G24: =UPPER(TRIM(F:F)) -> IT02 | H24: =VLOOKUP(G:G,Lookup_Departments!A:B,2,0) -> Information Technology | I24: 44815 | J24: =DATEDIF(I24,TODAY(),"Y") -> 3 | K24: 93956 | M24: 68.077465 | O24: =IF(M24>95,"Outstanding",IF(M24>85,"Exceeding",IF(M24>70,"Achieving",IF(M24>50,"Developing",IF(M24<50,"Needs Improvement"))))) -> Developing | P24: =IF(M24>95,"0.12",IF(M24>85,"0.08",IF(M24>70,"0.05",IF(M24>50,"0.02",IF(M24<50,"0"))))) -> 0.02 | Q24: =K24*P24 -> 1879.12 | R24: LEFT | S24: =PROPER(TRIM(R:R)) -> Left
B25: EMP032 | C25: Jessica | D25: Johnson | E25: Jessica Johnson | F25: FIN03 | G25: =UPPER(TRIM(F:F)) -> FIN03 | H25: =VLOOKUP(G:G,Lookup_Departments!A:B,2,0) -> Finance | I25: 42565 | J25: =DATEDIF(I25,TODAY(),"Y") -> 9 | K25: 100851 | M25: 68.077465 | O25: =IF(M25>95,"Outstanding",IF(M25>85,"Exceeding",IF(M25>70,"Achieving",IF(M25>50,"Developing",IF(M25<50,"Needs Improvement"))))) -> Developing | P25: =IF(M25>95,"0.12",IF(M25>85,"0.08",IF(M25>70,"0.05",IF(M25>50,"0.02",IF(M25<50,"0"))))) -> 0.02 | Q25: =K25*P25 -> 2017.02 | R25: ACTIVE | S25: =PROPER(TRIM(R:R)) -> Active
B26: EMP082 | C26: Ashley | D26: Williams | E26: Ashley Williams | F26: SAL05 | G26: =UPPER(TRIM(F:F)) -> SAL05 | H26: =VLOOKUP(G:G,Lookup_Departments!A:B,2,0) -> Sales | I26: 44728 | J26: =DATEDIF(I26,TODAY(),"Y") -> 4 | K26: 68655 | M26: 68.077465 | O26: =IF(M26>95,"Outstanding",IF(M26>85,"Exceeding",IF(M26>70,"Achieving",IF(M26>50,"Developing",IF(M26<50,"Needs Improvement"))))) -> Developing | P26: =IF(M26>95,"0.12",IF(M26>85,"0.08",IF(M26>70,"0.05",IF(M26>50,"0.02",IF(M26<50,"0"))))) -> 0.02 | Q26: =K26*P26 -> 1373.1 | R26: active | S26: =PROPER(TRIM(R:R)) -> Active
B27: EMP052 | C27: Williams | D27: Williams | E27: Williams Williams | F27: SAL05 | G27: =UPPER(TRIM(F:F)) -> SAL05 | H27: =VLOOKUP(G:G,Lookup_Departments!A:B,2,0) -> Sales | I27: 45134 | J27: =DATEDIF(I27,TODAY(),"Y") -> 2 | K27: 81205 | M27: 68.077465 | O27: =IF(M27>95,"Outstanding",IF(M27>85,"Exceeding",IF(M27>70,"Achieving",IF(M27>50,"Developing",IF(M27<50,"Needs Improvement"))))) -> Developing | P27: =IF(M27>95,"0.12",IF(M27>85,"0.08",IF(M27>70,"0.05",IF(M27>50,"0.02",IF(M27<50,"0"))))) -> 0.02 | Q27: =K27*P27 -> 1624.1 | R27: Active | S27: =PROPER(TRIM(R:R)) -> Active | Y27: Min_Score | Z27: Max_Score | AA27: Performance_Band | AB27: Bonus_Percentage
B28: EMP129 | C28: John | D28: Wilson | E28: John Wilson | F28: SAL05 | G28: =UPPER(TRIM(F:F)) -> SAL05 | H28: =VLOOKUP(G:G,Lookup_Departments!A:B,2,0) -> Sales | I28: 43732 | J28: =DATEDIF(I28,TODAY(),"Y") -> 6 | K28: 77610 | M28: 68.077465 | O28: =IF(M28>95,"Outstanding",IF(M28>85,"Exceeding",IF(M28>70,"Achieving",IF(M28>50,"Developing",IF(M28<50,"Needs Improvement"))))) -> Developing | P28: =IF(M28>95,"0.12",IF(M28>85,"0.08",IF(M28>70,"0.05",IF(M28>50,"0.02",IF(M28<50,"0"))))) -> 0.02 | Q28: =K28*P28 -> 1552.2 | R28: Active | S28: =PROPER(TRIM(R:R)) -> Active | Y28: 0 | Z28: 49 | AA28: Needs Improvement | AB28: 0
B29: EMP146 | C29: Thomas | D29: Rodriguez | E29: Thomas Rodriguez | F29: it02 | G29: =UPPER(TRIM(F:F)) -> IT02 | H29: =VLOOKUP(G:G,Lookup_Departments!A:B,2,0) -> Information Technology | I29: 44765 | J29: =DATEDIF(I29,TODAY(),"Y") -> 3 | K29: 50873 | M29: 68.077465 | O29: =IF(M29>95,"Outstanding",IF(M29>85,"Exceeding",IF(M29>70,"Achieving",IF(M29>50,"Developing",IF(M29<50,"Needs Improvement"))))) -> Developing | P29: =IF(M29>95,"0.12",IF(M29>85,"0.08",IF(M29>70,"0.05",IF(M29>50,"0.02",IF(M29<50,"0"))))) -> 0.02 | Q29: =K29*P29 -> 1017.46 | R29: Active | S29: =PROPER(TRIM(R:R)) -> Active | Y29: 50 | Z29: 69 | AA29: Developing | AB29: 0.02
B30: EMP099 | C30: Michael | D30: Wilson | E30: Michael Wilson | F30: fin03 | G30: =UPPER(TRIM(F:F)) -> FIN03 | H30: =VLOOKUP(G:G,Lookup_Departments!A:B,2,0) -> Finance | I30: 43233 | J30: =DATEDIF(I30,TODAY(),"Y") -> 8 | K30: 85312 | M30: 68.077465 | O30: =IF(M30>95,"Outstanding",IF(M30>85,"Exceeding",IF(M30>70,"Achieving",IF(M30>50,"Developing",IF(M30<50,"Needs Improvement"))))) -> Developing | P30: =IF(M30>95,"0.12",IF(M30>85,"0.08",IF(M30>70,"0.05",IF(M30>50,"0.02",IF(M30<50,"0"))))) -> 0.02 | Q30: =K30*P30 -> 1706.24 | R30: active | S30: =PROPER(TRIM(R:R)) -> Active | Y30: 70 | Z30: 84 | AA30: Achieving | AB30: 0.05
B31: EMP015 | C31: John | D31: Rodriguez | E31: John Rodriguez | F31: SAL05 | G31: =UPPER(TRIM(F:F)) -> SAL05 | H31: =VLOOKUP(G:G,Lookup_Departments!A:B,2,0) -> Sales | I31: 42202 | J31: =DATEDIF(I31,TODAY(),"Y") -> 10 | K31: 83603.931 | M31: 68.077465 | O31: =IF(M31>95,"Outstanding",IF(M31>85,"Exceeding",IF(M31>70,"Achieving",IF(M31>50,"Developing",IF(M31<50,"Needs Improvement"))))) -> Developing | P31: =IF(M31>95,"0.12",IF(M31>85,"0.08",IF(M31>70,"0.05",IF(M31>50,"0.02",IF(M31<50,"0"))))) -> 0.02 | Q31: =K31*P31 -> 1672.0786 | R31: active | S31: =PROPER(TRIM(R:R)) -> Active | Y31: 85 | Z31: 94 | AA31: Exceeding | AB31: 0.08
B32: EMP076 | C32: Thomas | D32: Hernandez | E32: Thomas Hernandez | F32: OPS06 | G32: =UPPER(TRIM(F:F)) -> OPS06 | H32: =VLOOKUP(G:G,Lookup_Departments!A:B,2,0) -> Operations | I32: 42221 | J32: =DATEDIF(I32,TODAY(),"Y") -> 10 | K32: 97055 | M32: 68.077465 | O32: =IF(M32>95,"Outstanding",IF(M32>85,"Exceeding",IF(M32>70,"Achieving",IF(M32>50,"Developing",IF(M32<50,"Needs Improvement"))))) -> Developing | P32: =IF(M32>95,"0.12",IF(M32>85,"0.08",IF(M32>70,"0.05",IF(M32>50,"0.02",IF(M32<50,"0"))))) -> 0.02 | Q32: =K32*P32 -> 1941.1 | R32: Active | S32: =PROPER(TRIM(R:R)) -> Active | Y32: 95 | Z32: 100 | AA32: Outstanding | AB32: 0.12
B33: EMP137 | C33: Michael | D33: Johnson | E33: Michael Johnson | F33: IT02 | G33: =UPPER(TRIM(F:F)) -> IT02 | H33: =VLOOKUP(G:G,Lookup_Departments!A:B,2,0) -> Information Technology | I33: 45195 | J33: =DATEDIF(I33,TODAY(),"Y") -> 2 | K33: 66069 | M33: 68.077465 | O33: =IF(M33>95,"Outstanding",IF(M33>85,"Exceeding",IF(M33>70,"Achieving",IF(M33>50,"Developing",IF(M33<50,"Needs Improvement"))))) -> Developing | P33: =IF(M33>95,"0.12",IF(M33>85,"0.08",IF(M33>70,"0.05",IF(M33>50,"0.02",IF(M33<50,"0"))))) -> 0.02 | Q33: =K33*P33 -> 1321.38 | R33: Active | S33: =PROPER(TRIM(R:R)) -> Active
B34: EMP056 | C34: Sarah | D34: Brown | E34: Sarah Brown | F34: it02 | G34: =UPPER(TRIM(F:F)) -> IT02 | H34: =VLOOKUP(G:G,Lookup_Departments!A:B,2,0) -> Information Technology | I34: 43626 | J34: =DATEDIF(I34,TODAY(),"Y") -> 7 | K34: 90157 | M34: 68.077465 | O34: =IF(M34>95,"Outstanding",IF(M34>85,"Exceeding",IF(M34>70,"Achieving",IF(M34>50,"Developing",IF(M34<50,"Needs Improvement"))))) -> Developing | P34: =IF(M34>95,"0.12",IF(M34>85,"0.08",IF(M34>70,"0.05",IF(M34>50,"0.02",IF(M34<50,"0"))))) -> 0.02 | Q34: =K34*P34 -> 1803.14 | R34: active | S34: =PROPER(TRIM(R:R)) -> Active
B35: EMP125 | C35: Jane | D35: Martinez | E35: Jane Martinez | F35: HR01 | G35: =UPPER(TRIM(F:F)) -> HR01 | H35: =VLOOKUP(G:G,Lookup_Departments!A:B,2,0) -> Human Resources | I35: 44578 | J35: =DATEDIF(I35,TODAY(),"Y") -> 4 | K35: 59899 | M35: 68.077465 | O35: =IF(M35>95,"Outstanding",IF(M35>85,"Exceeding",IF(M35>70,"Achieving",IF(M35>50,"Developing",IF(M35<50,"Needs Improvement"))))) -> Developing | P35: =IF(M35>95,"0.12",IF(M35>85,"0.08",IF(M35>70,"0.05",IF(M35>50,"0.02",IF(M35<50,"0"))))) -> 0.02 | Q35: =K35*P35 -> 1197.98 | R35: Active | S35: =PROPER(TRIM(R:R)) -> Active
B36: EMP085 | C36: Emily | D36: Jones | E36: Emily Jones | F36: FIN03 | G36: =UPPER(TRIM(F:F)) -> FIN03 | H36: =VLOOKUP(G:G,Lookup_Departments!A:B,2,0) -> Finance | I36: 42919 | J36: =DATEDIF(I36,TODAY(),"Y") -> 9 | K36: 113389 | M36: 68.077465 | O36: =IF(M36>95,"Outstanding",IF(M36>85,"Exceeding",IF(M36>70,"Achieving",IF(M36>50,"Developing",IF(M36<50,"Needs Improvement"))))) -> Developing | P36: =IF(M36>95,"0.12",IF(M36>85,"0.08",IF(M36>70,"0.05",IF(M36>50,"0.02",IF(M36<50,"0"))))) -> 0.02 | Q36: =K36*P36 -> 2267.78 | R36: ACTIVE | S36: =PROPER(TRIM(R:R)) -> Active
B37: EMP106 | C37: Brown | D37: Brown | E37: Brown Brown | F37: IT02 | G37: =UPPER(TRIM(F:F)) -> IT02 | H37: =VLOOKUP(G:G,Lookup_Departments!A:B,2,0) -> Information Technology | I37: 42248 | J37: =DATEDIF(I37,TODAY(),"Y") -> 10 | K37: 102691 | M37: 68.077465 | O37: =IF(M37>95,"Outstanding",IF(M37>85,"Exceeding",IF(M37>70,"Achieving",IF(M37>50,"Developing",IF(M37<50,"Needs Improvement"))))) -> Developing | P37: =IF(M37>95,"0.12",IF(M37>85,"0.08",IF(M37>70,"0.05",IF(M37>50,"0.02",IF(M37<50,"0"))))) -> 0.02 | Q37: =K37*P37 -> 2053.82 | R37: Active | S37: =PROPER(TRIM(R:R)) -> Active
B38: EMP043 | C38: John | D38: Wilson | E38: John Wilson | F38: OPS06 | G38: =UPPER(TRIM(F:F)) -> OPS06 | H38: =VLOOKUP(G:G,Lookup_Departments!A:B,2,0) -> Operations | I38: 44776 | J38: =DATEDIF(I38,TODAY(),"Y") -> 3 | K38: 111845 | M38: 68.077465 | O38: =IF(M38>95,"Outstanding",IF(M38>85,"Exceeding",IF(M38>70,"Achieving",IF(M38>50,"Developing",IF(M38<50,"Needs Improvement"))))) -> Developing | P38: =IF(M38>95,"0.12",IF(M38>85,"0.08",IF(M38>70,"0.05",IF(M38>50,"0.02",IF(M38<50,"0"))))) -> 0.02 | Q38: =K38*P38 -> 2236.9 | R38: active | S38: =PROPER(TRIM(R:R)) -> Active
B39: EMP068 | C39: Melissa | D39: Brown | E39: Melissa Brown | F39: SAL05 | G39: =UPPER(TRIM(F:F)) -> SAL05 | H39: =VLOOKUP(G:G,Lookup_Departments!A:B,2,0) -> Sales | I39: 44741 | J39: =DATEDIF(I39,TODAY(),"Y") -> 4 | K39: 69219 | M39: 68.077465 | O39: =IF(M39>95,"Outstanding",IF(M39>85,"Exceeding",IF(M39>70,"Achieving",IF(M39>50,"Developing",IF(M39<50,"Needs Improvement"))))) -> Developing | P39: =IF(M39>95,"0.12",IF(M39>85,"0.08",IF(M39>70,"0.05",IF(M39>50,"0.02",IF(M39<50,"0"))))) -> 0.02 | Q39: =K39*P39 -> 1384.38 | R39: Active | S39: =PROPER(TRIM(R:R)) -> Active
B40: EMP128 | C40: Michael | D40: Smith | E40: Michael Smith | F40: FIN03 | G40: =UPPER(TRIM(F:F)) -> FIN03 | H40: =VLOOKUP(G:G,Lookup_Departments!A:B,2,0) -> Finance | I40: 43949 | J40: =DATEDIF(I40,TODAY(),"Y") -> 6 | K40: 83603.931 | M40: 68.077465 | O40: =IF(M40>95,"Outstanding",IF(M40>85,"Exceeding",IF(M40>70,"Achieving",IF(M40>50,"Developing",IF(M40<50,"Needs Improvement"))))) -> Developing | P40: =IF(M40>95,"0.12",IF(M40>85,"0.08",IF(M40>70,"0.05",IF(M40>50,"0.02",IF(M40<50,"0"))))) -> 0.02 | Q40: =K40*P40 -> 1672.0786 | R40: left | S40: =PROPER(TRIM(R:R)) -> Left
...

Sheet Clean Data
B1: Emp ID | C1: Full Name | D1: Dept Code | E1: Department | F1: Hire Date | G1: Salary | H1: Average Salary | I1: Perf_Score | J1: Aveage score | K1: Employment Status | L1: Years of Service | M1: Performance Band | N1: Eligible Bonus Percentage | O1: Eligible Bonus Amount
B2: EMP127 | C2: Emily Brown | D2: IT02 | E2: Information Technology | F2: 43093 | G2: 50361 | H2: 83603.931 | I2: 52 | J2: 67.647512 | K2: Active | L2: 8 | M2: Developing | N2: 0.02 | O2: 1007.22
B3: EMP046 | C3: Richard Hernandez | D3: MKT04 | E3: Marketing | F3: 44659 | G3: 112673 | I3: 68.077465 | K3: Active | L3: 4 | M3: Developing | N3: 0.02 | O3: 2253.46
B4: EMP134 | D4: IT02 | E4: Information Technology | F4: 42431 | G4: 114425 | I4: 54 | K4: Left | L4: 10 | M4: Developing | N4: 0.02 | O4: 2288.5
B5: EMP139 | C5: John Martinez | D5: FIN03 | E5: Finance | F5: 45110 | G5: 103831 | I5: 70 | K5: Active | L5: 3 | M5: Developing | N5: 0.02 | O5: 2076.62
B6: EMP112 | C6: Thomas Smith | D6: IT02 | E6: Information Technology | F6: 44977 | G6: 73785 | I6: 40 | K6: Left | L6: 3 | M6: Needs Improvement | N6: 0 | O6: 0
B7: EMP030 | C7: Emily Johnson | D7: OPS06 | E7: Operations | F7: 43892 | G7: 115882 | I7: 49 | K7: Active | L7: 6 | M7: Needs Improvement | N7: 0 | O7: 0
B8: EMP096 | C8: John Wilson | D8: OPS06 | E8: Operations | F8: 45272 | G8: 59980 | I8: 70 | K8: Left | L8: 2 | M8: Developing | N8: 0.02 | O8: 1199.6
B9: EMP098 | C9: Jessica Smith | D9: OPS06 | E9: Operations | F9: 44174 | G9: 68728 | I9: 45 | K9: Active | L9: 5 | M9: Needs Improvement | N9: 0 | O9: 0
B10: EMP095 | C10: Rodriguez Rodriguez | D10: FIN03 | E10: Finance | F10: 43107 | G10: 102139 | I10: 79 | K10: Active | L10: 8 | M10: Achieving | N10: 0.05 | O10: 5106.95
B11: EMP140 | C11: Michael Martinez | D11: SAL05 | E11: Sales | F11: 42676 | G11: 94998 | I11: 58 | K11: Active | L11: 9 | M11: Developing | N11: 0.02 | O11: 1899.96
B12: EMP020 | C12: Emily Miller | D12: SAL05 | E12: Sales | F12: 43911 | G12: 118635 | I12: 49 | K12: Active | L12: 6 | M12: Needs Improvement | N12: 0 | O12: 0
B13: EMP057 | C13: Emily Hernandez | D13: IT02 | E13: Information Technology | F13: 42425 | G13: 76918 | I13: 62 | K13: Active | L13: 10 | M13: Developing | N13: 0.02 | O13: 1538.36
B14: EMP016 | C14: Jane Williams | D14: MKT04 | E14: Marketing | F14: 44364 | G14: 61408 | I14: 48 | K14: Active | L14: 5 | M14: Needs Improvement | N14: 0 | O14: 0
B15: EMP070 | C15: Jane Miller | D15: MKT04 | E15: Marketing | F15: 44001 | G15: 99990 | I15: 54 | K15: Active | L15: 6 | M15: Developing | N15: 0.02 | O15: 1999.8
B16: EMP025 | C16: Robert Jones | D16: MKT04 | E16: Marketing | F16: 43820 | G16: 80385 | I16: 68.077465 | K16: Active | L16: 6 | M16: Developing | N16: 0.02 | O16: 1607.7
... B151: EMP122 | C151: Amanda Brown | D151: IT02 | E151: Information Technology | F151: 44848 | G151: 118634 | I151: 91 | K151: Active | L151: 3 | M151: Exceeding | N151: 0.08 | O151: 9490.72
B152: EMP142
B153: EMP021
B154: EMP072
B155: EMP107
B156: EMP015
B157: EMP093
B158: EMP103

Sheet Analysis 
A3: Total Head Count | B3: Sum of Salary | C3: Average of Salary | D3: Sum of Eligible Bonus Amount | E3: OVERALL ATRRITION
A4: 140 | B4: 11636997 | C4: 83121.405 | D4: 305143.17 | E4: =Attritionrate+RESIGNEDTOTAL -> 0.17142857
A6: Head count and Aveage Salary By Department | E6: Average performance Score Employment status
A7: Department | B7: Average of Salary | C7: Total Head count | E7: Performance Band | F7: Average of Perf_Score
A8: Finance | B8: 87173.576 | C8: 17 | E8: Active | F8: 67.677392
A9: Human Resources | B9: 87534.467 | C9: 17 | E9: Left | F9: 67.128521
A10: Information Technology | B10: 80377.696 | C10: 34
A11: Marketing | B11: 85407.944 | C11: 19
A12: Operations | B12: 76219.328 | C12: 24 | E12: Employment Status By Performance Score
A13: Sales | B13: 85589.776 | C13: 29 | E13: Performance Band | F13: Count of Perf_Score
E14: Active | F14: 0.82857143
E15: Left | F15: 0.17142857
A17: Attrition Rate By department
A18: Employment Status | B18: Department | C18: Percentage Employment Status | E18: Performamnce Band By Payout Bonus
A19: Active | B19: Information Technology | C19: 0.2 | E19: Performance Band | F19: Total of Eligible Bonus Amount
B20: Sales | C20: 0.17857143 | E20: Needs Improvement | F20: 0
B21: Operations | C21: 0.12857143 | E21: Outstanding | F21: 17840.272
B22: Marketing | C22: 0.11428571 | E22: Exceeding | F22: 55646.72
B23: Human Resources | C23: 0.10714286 | E23: Achieving | F23: 64258.797
B24: Finance | C24: 0.1 | E24: Developing | F24: 167397.38
A25: Active Total | C25: 0.82857143
A26: Left | B26: Operations | C26: 0.042857143
B27: Information Technology | C27: 0.042857143 | E27: Employee couny By Emplotment Status across the Years
B28: Sales | C28: 0.028571429 | E28: Years | F28: (All)
B29: Finance | C29: 0.021428571
B30: Marketing | C30: 0.021428571 | E30: Employment Status | F30: Department | G30: Count of Emp ID
B31: Human Resources | C31: 0.014285714 | E31: Active | F31: Finance | G31: 14
A32: Left Total | C32: 0.17142857 | F32: Human Resources | G32: 15
F33: Marketing | G33: 16
F34: Operations | G34: 18
F35: Sales | G35: 25
F36: Information Technology | G36: 28
E37: Active Total | G37: 116
E38: Left | F38: Human Resources | G38: 2
F39: Finance | G39: 3
F40: Marketing | G40: 3
F41: Sales | G41: 4
F42: Information Technology | G42: 6
F43: Operations | G43: 6
E44: Left Total | G44: 24

Sheet HR Dashboard
